<!-- These are atlas torso and limb models, for full Atlas robot model, please see
     xacro files containing fully assembed robots in atlas_description/robots/ -->
<robot name="drc_skeleton">
    <link name="BASE0">
        <inertial>
            <mass value="14.2529" />
            <origin xyz="0.0111 0 0.0271" rpy="0 -0 0" />
            <inertia ixx="0.1244" ixy="0.0008" ixz="-0.0007"
                     iyy="0.0958" iyz="-0.0005"
                     izz="0.1167" />
        </inertial>
        <visual>
            <origin rpy="1.5707963267949 0 0" xyz="0.046 0.0 -0.02"/>
            <geometry>
              <cylinder radius="0.11" length="0.06"/>
            </geometry>
        </visual>
    </link>
    <link name="l_foot">
        <inertial>
            <mass value="1.634" />
            <origin xyz="0.027 0 -0.067" rpy="0 -0 0" />
            <inertia ixx="0.002" ixy="0" ixz="0" iyy="0.007" iyz="0" izz="0.008" />
        </inertial>
        <visual>
            <origin xyz="0.048 0 -0.056119" rpy="0 0 0"/>
            <geometry>
              <box size="0.26 0.124887 0.05"/>
            </geometry>
        </visual>
        <!-- bottom -->
        <collision group="default">
          <origin xyz="0.048 0 -0.056119" rpy="0 0 0"/>
          <geometry>
            <box size="0.26 0.124887 0.05"/>
          </geometry>
        </collision>
    </link>
    <link name="l_lglut">
        <inertial>
            <mass value="0.69" />
            <origin xyz="0.0133341 0.0170484 -0.0312052" rpy="0 -0 0" />
            <inertia ixx="0.000691326" ixy="-2.24344e-05" ixz="2.50508e-06" iyy="0.00126856" iyz="0.000137862" izz="0.00106487" />
        </inertial>
        <visual>
            <origin rpy="1.5707963267949 0 0" xyz="0.049968 0.022488 -0.0501165"/>
            <geometry>
              <cylinder radius="0.02009687" length="0.060306"/>
            </geometry>
        </visual>
    </link>
    <link name="l_lleg">
        <inertial>
            <mass value="4.367" />
            <origin xyz="0.001 0 -0.187" rpy="0 -0 0" />
            <inertia ixx="0.077" ixy="0" ixz="-0.003" iyy="0.076" iyz="0" izz="0.01" />
        </inertial>
        <visual>
            <origin rpy="0 0.10 0" xyz="0.02 0.00295 -0.18"/>
            <geometry>
              <cylinder radius="0.07" length="0.40"/>
            </geometry>
        </visual>
    </link>
    <link name="l_talus">
        <inertial>
            <mass value="0.1" />
            <origin xyz="0 0 0" rpy="0 -0 0" />
            <inertia ixx="1.01674e-05" ixy="0" ixz="0" iyy="8.42775e-06" iyz="0" izz="1.30101e-05" />
        </inertial>
        <visual>
            <origin rpy="0 1.5707963267949 0" xyz="0 0 0"/>
            <geometry>
                <cylinder radius="0.010181" length="0.029542"/>
            </geometry>
        </visual>
    </link>
    <link name="l_uglut">
        <inertial>
            <mass value="0.5166" />
            <origin xyz="0.00529262 -0.00344732 0.00313046" rpy="0 -0 0" />
            <inertia ixx="0.00074276" ixy="-3.79607e-08" ixz="-2.79549e-05" iyy="0.000688179" iyz="-3.2735e-08" izz="0.00041242" />
        </inertial>
        <visual>
            <origin rpy="0 1.5707963267949 0" xyz="0 0 0"/>
            <geometry>
                <cylinder radius="0.019096" length="0.078396"/>
            </geometry>
        </visual>
    </link>
    <link name="l_uleg">
        <inertial>
            <mass value="7.34" />
            <origin xyz="0 0 -0.21" rpy="0 -0 0" />
            <inertia ixx="0.09" ixy="0" ixz="0" iyy="0.09" iyz="0" izz="0.02" />
        </inertial>
        <visual>
            <origin rpy="0 0 0" xyz="-0.0179 0.02085 -0.13"/>
            <geometry>
                <cylinder radius="0.1" length="0.10"/>
            </geometry>
        </visual>
    </link>
    <link name="r_foot">
        <inertial>
            <mass value="1.634" />
            <origin xyz="0.027 0 -0.067" rpy="0 -0 0" />
            <inertia ixx="0.002" ixy="0" ixz="0" iyy="0.007" iyz="0" izz="0.008" />
        </inertial>
        <visual>
            <origin xyz="0.048 0 -0.056119" rpy="0 0 0"/>
            <geometry>
                <box size="0.26 0.124887 0.05"/>
            </geometry>
        </visual>
        <!-- bottom -->
        <collision group="default">
          <origin xyz="0.048 0 -0.056119" rpy="0 0 0"/>
          <geometry>
            <box size="0.26 0.124887 0.05"/>
          </geometry>
        </collision>
    </link>
    <link name="r_lglut">
        <inertial>
            <mass value="0.69" />
            <origin xyz="0.0133341 -0.0170484 -0.0312052" rpy="0 -0 0" />
            <inertia ixx="0.000691326" ixy="2.24344e-05" ixz="2.50508e-06" iyy="0.00126856" iyz="-0.000137862" izz="0.00106487" />
        </inertial>
        <visual>
            <origin rpy="1.5707963267949 0 0" xyz="0.049968 -0.022488 -0.0501165"/>
            <geometry>
                <cylinder radius="0.02009687" length="0.060306"/>
            </geometry>
        </visual>
    </link>
    <link name="r_lleg">
        <inertial>
            <mass value="4.367" />
            <origin xyz="0.001 0 -0.187" rpy="0 -0 0" />
            <inertia ixx="0.077" ixy="-0" ixz="-0.003" iyy="0.076" iyz="-0" izz="0.01" />
        </inertial>
        <visual>
            <origin rpy="0 0.10 0" xyz="0.02 -0.00295 -0.18"/>
            <geometry>
                <cylinder radius="0.07" length="0.40"/>
            </geometry>
        </visual>
    </link>
    <link name="r_talus">
        <inertial>
            <mass value="0.1" />
            <origin xyz="0 0 0" rpy="0 -0 0" />
            <inertia ixx="1.01674e-05" ixy="0" ixz="0" iyy="8.42775e-06" iyz="0" izz="1.30101e-05" />
        </inertial>
        <visual>
            <origin rpy="0 1.5707963267949 0" xyz="0 0 0"/>
            <geometry>
                <cylinder radius="0.010181" length="0.029542"/>
            </geometry>
        </visual>
    </link>
    <link name="r_uglut">
        <inertial>
            <mass value="0.5166" />
            <origin xyz="0.00529262 0.00344732 0.00313046" rpy="0 -0 0" />
            <inertia ixx="0.00074276" ixy="3.79607e-08" ixz="-2.79549e-05" iyy="0.000688179" iyz="3.2735e-08" izz="0.00041242" />
        </inertial>
        <visual>
            <origin rpy="0 1.5707963267949 0" xyz="0 0 0"/>
            <geometry>
                <cylinder radius="0.019096" length="0.078396"/>
            </geometry>
        </visual>
    </link>
    <link name="r_uleg">
        <inertial>
            <mass value="7.34" />
            <origin xyz="0 0 -0.21" rpy="0 -0 0" />
            <inertia ixx="0.09" ixy="0" ixz="0" iyy="0.09" iyz="0" izz="0.02" />
        </inertial>
        <visual>
            <origin rpy="0 0 0" xyz="-0.0179 -0.02085 -0.13"/>
            <geometry>
                <cylinder radius="0.1" length="0.10"/>
            </geometry>
        </visual>
    </link>
    <joint name="l_leg_kny4" type="revolute">
        <origin xyz="-0.05 0 -0.374" rpy="0 -0 0" />
        <axis xyz="0 1 0" />
        <parent link="l_uleg" />
        <child link="l_lleg" />
        <dynamics damping="1.0" friction="0" />
        <limit effort="400" velocity="12" lower="0" upper="2.45" />
        <safety_controller k_position="100" k_velocity="100" soft_lower_limit="-10" soft_upper_limit="12.45" />
    </joint>
    <joint name="l_leg_lax6" type="revolute">
        <origin xyz="0 0 0" rpy="0 -0 0" />
        <axis xyz="1 0 0" />
        <parent link="l_talus" />
        <child link="l_foot" />
        <dynamics damping="1.0" friction="0" />
        <limit effort="90" velocity="12" lower="-0.436" upper="0.436" />
        <safety_controller k_position="100" k_velocity="100" soft_lower_limit="-10.436" soft_upper_limit="10.436" />
    </joint>
    <joint name="l_leg_lhy3" type="revolute">
        <origin xyz="0.05 0 -0.05" rpy="0 -0 0" />
        <axis xyz="0 1 0" />
        <parent link="l_lglut" />
        <child link="l_uleg" />
        <dynamics damping="1.0" friction="0" />
        <limit effort="260" velocity="12" lower="-1.75" upper="0.524" />
        <safety_controller k_position="100" k_velocity="100" soft_lower_limit="-11.75" soft_upper_limit="10.524" />
    </joint>
    <joint name="l_leg_mhx2" type="revolute">
        <origin xyz="0 0 0" rpy="0 -0 0" />
        <axis xyz="1 0 0" />
        <parent link="l_uglut" />
        <child link="l_lglut" />
        <dynamics damping="1.0" friction="0" />
        <limit effort="180" velocity="12" lower="-0.47" upper="0.495" />
        <safety_controller k_position="100" k_velocity="100" soft_lower_limit="-10.47" soft_upper_limit="10.495" />
    </joint>
    <joint name="l_leg_uay5" type="revolute">
        <origin xyz="0 0 -0.422" rpy="0 -0 0" />
        <axis xyz="0 1 0" />
        <parent link="l_lleg" />
        <child link="l_talus" />
        <dynamics damping="1.0" friction="0" />
        <limit effort="220" velocity="12" lower="-0.9" upper="0.698" />
        <safety_controller k_position="100" k_velocity="100" soft_lower_limit="-10.698" soft_upper_limit="10.698" />
    </joint>
    <joint name="l_leg_uhz1" type="revolute">
        <origin xyz="0 0.089 0" rpy="0 -0 0" />
        <axis xyz="0 0 1" />
        <parent link="BASE0" />
        <child link="l_uglut" />
        <dynamics damping="1.0" friction="0" />
        <limit effort="110" velocity="12" lower="-0.32" upper="1.14" />
        <safety_controller k_position="100" k_velocity="100" soft_lower_limit="-10.32" soft_upper_limit="11.14" />
    </joint>
    <joint name="r_leg_kny4" type="revolute">
        <origin xyz="-0.05 0 -0.374" rpy="0 -0 0" />
        <axis xyz="0 1 0" />
        <parent link="r_uleg" />
        <child link="r_lleg" />
        <dynamics damping="1.0" friction="0" />
        <limit effort="400" velocity="12" lower="0" upper="2.45" />
        <safety_controller k_position="100" k_velocity="100" soft_lower_limit="-10" soft_upper_limit="12.45" />
    </joint>
    <joint name="r_leg_lax6" type="revolute">
        <origin xyz="0 0 0" rpy="0 -0 0" />
        <axis xyz="1 0 0" />
        <parent link="r_talus" />
        <child link="r_foot" />
        <dynamics damping="1.0" friction="0" />
        <limit effort="90" velocity="12" lower="-0.436" upper="0.436" />
        <safety_controller k_position="100" k_velocity="100" soft_lower_limit="-10.436" soft_upper_limit="10.436" />
    </joint>
    <joint name="r_leg_lhy3" type="revolute">
        <origin xyz="0.05 0 -0.05" rpy="0 -0 0" />
        <axis xyz="0 1 0" />
        <parent link="r_lglut" />
        <child link="r_uleg" />
        <dynamics damping="1.0" friction="0" />
        <limit effort="260" velocity="12" lower="-1.745" upper="0.524" />
        <safety_controller k_position="100" k_velocity="100" soft_lower_limit="-11.745" soft_upper_limit="10.524" />
    </joint>
    <joint name="r_leg_mhx2" type="revolute">
        <origin xyz="0 0 0" rpy="0 -0 0" />
        <axis xyz="1 0 0" />
        <parent link="r_uglut" />
        <child link="r_lglut" />
        <dynamics damping="1.0" friction="0" />
        <limit effort="180" velocity="12" lower="-0.495" upper="0.47" />
        <safety_controller k_position="100" k_velocity="100" soft_lower_limit="-10.495" soft_upper_limit="10.47" />
    </joint>
    <joint name="r_leg_uay5" type="revolute">
        <origin xyz="0 0 -0.422" rpy="0 -0 0" />
        <axis xyz="0 1 0" />
        <parent link="r_lleg" />
        <child link="r_talus" />
        <dynamics damping="1.0" friction="0" />
        <limit effort="220" velocity="12" lower="-0.9" upper="0.698" />
        <safety_controller k_position="100" k_velocity="100" soft_lower_limit="-10.698" soft_upper_limit="10.698" />
    </joint>
    <joint name="r_leg_uhz1" type="revolute">
        <origin xyz="0 -0.089 0" rpy="0 -0 0" />
        <axis xyz="0 0 1" />
        <parent link="BASE0" />
        <child link="r_uglut" />
        <dynamics damping="1.0" friction="0" />
        <limit effort="110" velocity="12" lower="-1.14" upper="0.32" />
        <safety_controller k_position="100" k_velocity="100" soft_lower_limit="-11.14" soft_upper_limit="10.32" />
    </joint>
</robot>
