<robot name="links">
<!-- ROBOT LINKS -->
    <link name="ABDOMEN">
            <inertial>
              <origin xyz="0 0 0"/>
                    <mass value="3.0"/>
                    <inertia ixx="1.0"  ixy="0.0"  ixz="0.0" iyx="0.0"  iyy="1.0" iyz="0.0"  izx="0.0"  izy="0.0"  izz="1.0" />
            </inertial>
            <visual>
                    <origin xyz="0 0 0" rpy="0.0 0.0 0.0"/>
                    <geometry>
                        <box size="0.0860 0.101 0.0356"/>
                    </geometry>
                    <material name="blue">
                            <color rgba=".20 .20 .100 1.0"/>
                    </material>
            </visual>
            <collision>
                    <origin xyz="0 0 0" rpy="0.000000 0.000000 0.000000"/>
                    <geometry>
                    <box size="0.0860 0.101 0.0356"/>
                    </geometry>
            </collision>
    </link>
    <link name="THORAX">
            <inertial>
              <origin xyz="0.02525 0 0"/>
                    <mass value="2.0"/>
                    <inertia ixx="1.0"  ixy="0.0"  ixz="0.0" iyx="0.0"  iyy="1.0" iyz="0.0"  izx="0.0"  izy="0.0"  izz="1.0" />
            </inertial>
            <visual>
              <origin xyz="0.02525 0 0"/>
                    <geometry>
                    <box size="0.0355 0.101 0.0356"/>
                    </geometry>
                    <material name="blue">
                        <color rgba=".20 .20 .100 1.0"/>
                    </material>
            </visual>
            <collision>
              <origin xyz="0.02525 0 0"/>
                    <geometry>
                    <box size="0.0355 0.101 0.0356"/>
                    </geometry>
            </collision>
    </link>
    <!-- LF_LEG LINKS -->
    <link name="LF_HIP">
            <inertial>
                    <origin xyz="0.02525 0 0"/>
                    <mass value="1.0"/>
                    <inertia ixx="1.0"  ixy="0.0"  ixz="0.0" iyx="0.0"  iyy="1.0" iyz="0.0"  izx="0.0"  izy="0.0"  izz="1.0" />
            </inertial>
            <visual>
                <origin xyz="0.02525 0 0"/>
                    <geometry>
                    <box size="0.0505 0.0355 0.0356"/>
                    </geometry>
                    <material name="Red">
                            <color rgba="1 0 0 1.0"/>
                    </material>
            </visual>
            <collision>
            <origin xyz="0.02525 0 0"/>
                    <geometry>
                    <box size="0.0505 0.0355 0.0356"/>
                    </geometry>
            </collision>
    </link>
    <link name="LF_ULEG">
            <inertial>
            <origin xyz="0.02525 0 0"/>
                    <mass value="1.0"/>
                    <inertia ixx="1.0"  ixy="0.0"  ixz="0.0" iyx="0.0"  iyy="1.0" iyz="0.0"  izx="0.0"  izy="0.0"  izz="1.0" />
            </inertial>
            <visual>
            <origin xyz="0.02525 0 0"/>
                    <geometry>
                    <box size="0.0505 0.0355 0.0356"/>
                    </geometry>
                    <material name="Red">
                    </material>
            </visual>
            <collision>
            <origin xyz="0.02525 0 0"/>
                    <geometry>
                    <box size="0.0505 0.0355 0.0356"/>
                    </geometry>
            </collision>
    </link>
    <link name="LF_LLEG">
            <inertial>
            <origin xyz="0.04 0 0" rpy="0.7854 0 0"/>
                    <mass value="1.0"/>
                    <inertia ixx="0.1"  ixy="0.0"  ixz="0.0" iyx="0.0"  iyy="1.0" iyz="0.0"  izx="0.0"  izy="0.0"  izz="1.0" />
            </inertial>
            <visual>
            <origin xyz="0.04 0 0" rpy="0.7854 0 0"/>
                    <geometry>
                    <box size="0.08 0.01 0.01"/>
                    </geometry>
                    <material name="Red">
                    </material>
            </visual>
            <collision>
            <origin xyz="0.04 0 0" rpy="0.7854 0 0"/>
                    <geometry>
                    <box size="0.08 0.01 0.01"/>
                    </geometry>
            </collision>
    </link>

    <!-- RF_LEG LINKS -->
    <link name="RF_HIP">
            <inertial>
            <origin xyz="0.02525 0 0"/>
                    <mass value="1.0"/>
                    <inertia ixx="1.0"  ixy="0.0"  ixz="0.0" iyx="0.0"  iyy="1.0" iyz="0.0"  izx="0.0"  izy="0.0"  izz="1.0" />
            </inertial>
            <visual>
            <origin xyz="0.02525 0 0"/>
                    <geometry>
                    <box size="0.0505 0.0355 0.0356"/>
                    </geometry>
                    <material name="Red">
                    </material>
            </visual>
            <collision>
            <origin xyz="0.02525 0 0"/>
                    <geometry>
                    <box size="0.0505 0.0355 0.0356"/>
                    </geometry>
            </collision>
    </link>
    <link name="RF_ULEG">
            <inertial>
            <origin xyz="0.02525 0 0"/>
                    <mass value="1.0"/>
                    <inertia ixx="1.0"  ixy="0.0"  ixz="0.0" iyx="0.0"  iyy="1.0" iyz="0.0"  izx="0.0"  izy="0.0"  izz="1.0" />
            </inertial>
            <visual>
            <origin xyz="0.02525 0 0"/>
                    <geometry>
                    <box size="0.0505 0.0355 0.0356"/>
                    </geometry>
                    <material name="Red">
                    </material>
            </visual>
            <collision>
            <origin xyz="0.02525 0 0"/>
                    <geometry>
                    <box size="0.0505 0.0355 0.0356"/>
                    </geometry>
            </collision>
    </link>
    <link name="RF_LLEG">
            <inertial>
            <origin xyz="0.04 0 0"  rpy="0.7854 0 0"/>
                    <mass value="1.0"/>
                    <inertia ixx="0.1"  ixy="0.0"  ixz="0.0" iyx="0.0"  iyy="1.0" iyz="0.0"  izx="0.0"  izy="0.0"  izz="1.0" />
            </inertial>
            <visual>
            <origin xyz="0.04 0 0"  rpy="0.7854 0 0"/>
                    <geometry>
                    <box size="0.08 0.01 0.01"/>
                    </geometry>
                    <material name="Red">
                    </material>
            </visual>
            <collision>
            <origin xyz="0.04 0 0"  rpy="0.7854 0 0"/>
                    <geometry>
                    <box size="0.08 0.01 0.01"/>
                    </geometry>
            </collision>
    </link>
    <!-- LH_LEG LINKS -->
    <link name="LH_HIP">
            <inertial>
            <origin xyz="0.0355 0 0"/>
                    <mass value="1.0"/>
                    <inertia ixx="1.0"  ixy="0.0"  ixz="0.0" iyx="0.0"  iyy="1.0" iyz="0.0"  izx="0.0"  izy="0.0"  izz="1.0" />
            </inertial>
            <visual>
            <origin xyz="0.0355 0 0"/>
                    <geometry>
                    <box size="0.0611 0.0402 0.041"/>
                    </geometry>
                    <material name="Red">
                    </material>
            </visual>
            <collision>
            <origin xyz="0.0355 0 0"/>
                    <geometry>
                    <box size="0.0611 0.0402 0.041"/>
                    </geometry>
            </collision>
    </link>
    <link name="LH_ULEG">
            <inertial>
            <origin xyz="0.02525 0 0"/>
                    <mass value="1.0"/>
                    <inertia ixx="1.0"  ixy="0.0"  ixz="0.0" iyx="0.0"  iyy="1.0" iyz="0.0"  izx="0.0"  izy="0.0"  izz="1.0" />
            </inertial>
            <visual>
            <origin xyz="0.02525 0 0"/>
                    <geometry>
                    <box size="0.0505 0.0355 0.0356"/>
                    </geometry>
                    <material name="Red">
                    </material>
            </visual>
            <collision>
            <origin xyz="0.02525 0 0"/>
                    <geometry>
                    <box size="0.0505 0.0355 0.0356"/>
                    </geometry>
            </collision>
    </link>
    <link name="LH_LLEG">
            <inertial>
            <origin xyz="0.04 0 0"  rpy="0.7854 0 0"/>
                    <mass value="1.0"/>
                    <inertia ixx="0.1"  ixy="0.0"  ixz="0.0" iyx="0.0"  iyy="1.0" iyz="0.0"  izx="0.0"  izy="0.0"  izz="1.0" />
            </inertial>
            <visual>
            <origin xyz="0.04 0 0" rpy="0.7854 0 0"/>
                    <geometry>
                    <box size="0.08 0.01 0.01"/>
                    </geometry>
                    <material name="Red">
                    </material>
            </visual>
            <collision>
            <origin xyz="0.04 0 0" rpy="0.7854 0 0"/>
                    <geometry>
                    <box size="0.08 0.01 0.01"/>
                    </geometry>
            </collision>
    </link>
    <!-- RH_LEG LINKS -->
    <link name="RH_HIP">
            <inertial>
            <origin xyz="0.0355 0 0"/>
                    <mass value="1.0"/>
                    <inertia ixx="1.0"  ixy="0.0"  ixz="0.0" iyx="0.0"  iyy="1.0" iyz="0.0"  izx="0.0"  izy="0.0"  izz="1.0" />
            </inertial>
            <visual>
            <origin xyz="0.0355 0 0"/>
                    <geometry>
                    <box size="0.0611 0.0402 0.041"/>
                    </geometry>
                    <material name="Red">
                    </material>
            </visual>
            <collision>
            <origin xyz="0.0355 0 0"/>
                    <geometry>
                    <box size="0.0611 0.0402 0.041"/>
                    </geometry>
            </collision>
    </link>
    <link name="RH_ULEG">
            <inertial>
            <origin xyz="0.02525 0 0"/>
                    <mass value="1.0"/>
                    <inertia ixx="1.0"  ixy="0.0"  ixz="0.0" iyx="0.0"  iyy="1.0" iyz="0.0"  izx="0.0"  izy="0.0"  izz="1.0" />
            </inertial>
            <visual>
            <origin xyz="0.02525 0 0"/>
                    <geometry>
                    <box size="0.0505 0.0355 0.0356"/>
                    </geometry>
                    <material name="Red">
                    </material>
            </visual>
            <collision>
            <origin xyz="0.02525 0 0"/>
                    <geometry>
                    <box size="0.0505 0.0355 0.0356"/>
                    </geometry>
            </collision>
    </link>
    <link name="RH_LLEG">
            <inertial>
                    <origin xyz="0.04 0 0" rpy="0.7854 0 0"/>
                    <mass value="1.0"/>
                    <inertia ixx="0.1"  ixy="0.0"  ixz="0.0" iyx="0.0"  iyy="1.0" iyz="0.0"  izx="0.0"  izy="0.0"  izz="1.0" />
            </inertial>
            <visual>
            <origin xyz="0.04 0 0" rpy="0.7854 0 0"/>
                    <geometry>
                    <box size="0.08 0.01 0.01"/>
                    </geometry>
                    <material name="Red">
                    </material>
            </visual>
            <collision>
            <origin xyz="0.04 0 0" rpy="0.7854 0 0"/>
                    <geometry>
                    <box size="0.08 0.01 0.01"/>
                    </geometry>
            </collision>
    </link>
<!-- ROBOT JOINTS -->
    <joint name="BODY_JOINT" type="revolute">
            <origin xyz="0.043 0.0 0.0" rpy="0.0 0.0 0.0"/>
            <parent link="ABDOMEN"/>
            <child link="THORAX"/>
            <axis xyz="0 1 0"/>
            <limits upper="0.7854" lower="-0.7854" />
    </joint>

   <!-- LF_LEG JOINTS -->
   <joint name="LF_HIP_AA" type="revolute">
           <origin xyz="0.043 0.0475 0.0" rpy="0 0 0"/>
           <parent link="THORAX"/>
           <child link="LF_HIP"/>
           <axis xyz="1 0 0"/>
            <limits upper="2.3562" lower="-2.3562" />
   </joint>
    <joint name="LF_HIP_FE" type="revolute">
            <origin xyz="0.0505 0.0 0.0" rpy="0 0 0.0"/>
            <parent link="LF_HIP"/>
            <child link="LF_ULEG"/>
            <axis xyz="0 1 0"/>
            <limits upper="2.3562" lower="-2.3562" />
    </joint>
    <joint name="LF_LEG_FE" type="revolute">
            <origin xyz="0.0505 0.0 0.0" rpy="0.0 0.0 0.0"/>
            <parent link="LF_ULEG"/>
            <child link="LF_LLEG"/>
            <axis xyz="0 1 0"/>
            <limits upper="2.3562" lower="-2.3562" />
    </joint>

    <!-- RF_LEG JOINTS -->
    <joint name="RF_HIP_AA" type="revolute">
            <origin xyz="0.043 -0.0475 0.0" rpy="0 0 0"/>
            <parent link="THORAX"/>
            <child link="RF_HIP"/>
            <axis xyz="1 0 0"/>
            <limits upper="2.3562" lower="-2.3562" />
    </joint>
    <joint name="RF_HIP_FE" type="revolute">
            <origin xyz="0.0505 0.0 0.0" rpy="0 0 0.0"/>
            <parent link="RF_HIP"/>
            <child link="RF_ULEG"/>
            <axis xyz="0 1 0"/>
            <limits upper="2.3562" lower="-2.3562" />
    </joint>
    <joint name="RF_LEG_FE" type="revolute">
            <origin xyz="0.0505 0.0 0.0" rpy="0.0 0.0 0.0"/>
            <parent link="RF_ULEG"/>
            <child link="RF_LLEG"/>
            <axis xyz="0 1 0"/>
            <limits upper="2.3562" lower="-2.3562" />
    </joint>

    <!-- LH_LEG JOINTS -->
    <joint name="LH_HIP_AA" type="revolute">
            <origin xyz="-0.043 0.0475 0.0" rpy="0 0 3.1416"/>
            <parent link="ABDOMEN"/>
            <child link="LH_HIP"/>
            <axis xyz="1 0 0"/>
            <limits upper="2.3562" lower="-2.3562" />
    </joint>
    <joint name="LH_HIP_FE" type="revolute">
            <origin xyz="0.0611 0.0 0.0" rpy="0 0 0"/>
            <parent link="LH_HIP"/>
            <child link="LH_ULEG"/>
            <axis xyz="0 1 0"/>
            <limits upper="2.3562" lower="-2.3562" />
    </joint>
    <joint name="LH_LEG_FE" type="revolute">
            <origin xyz="0.0505 0.0 0.0" rpy="0.0 0.0 0.0"/>
            <parent link="LH_ULEG"/>
            <child link="LH_LLEG"/>
            <axis xyz="0 1 0"/>
            <limits upper="2.3562" lower="-2.3562" />
    </joint>

    <!-- RH_LEG JOINTS -->
    <joint name="RH_HIP_AA" type="revolute">
            <origin xyz="-0.043 -0.0475 0.0" rpy="0 0 3.1416"/>
            <parent link="ABDOMEN"/>
            <child link="RH_HIP"/>
            <axis xyz="1 0 0"/>
            <limits upper="2.3562" lower="-2.3562" />
    </joint>
    <joint name="RH_HIP_FE" type="revolute">
            <origin xyz="0.0611 0.0 0.0" rpy="0 0 0"/>
            <parent link="RH_HIP"/>
            <child link="RH_ULEG"/>
            <axis xyz="0 1 0"/>
            <limits upper="2.3562" lower="-2.3562" />
    </joint>
    <joint name="RH_LEG_FE" type="revolute">
            <origin xyz="0.0505 0.0 0.0" rpy="0 0.0 0.0"/>
            <parent link="RH_ULEG"/>
            <child link="RH_LLEG"/>
            <axis xyz="0 1 0"/>
            <limits upper="2.3562" lower="-2.3562" />
    </joint>

 </robot>
