<robot name="links">
<!-- ROBOT LINKS -->
    <link name="ABDOMEN">
            <inertial>
              <origin xyz="0 0 0"/>
                    <mass value="25.000000"/>
                    <inertia ixx="1.259832"  ixy="0.030529"  ixz="-0.058400" iyx="0.030529"  iyy="6.565043" iyz="-0.026018"  izx="-0.058400"  izy="-0.026018"  izz="6.692983" />
            </inertial>
            <visual>
                    <origin xyz="0 0 0" rpy="0.0 0.0 0.0"/>
                    <geometry>
                        <box size="0.0355 0.101 0.0356"/>
                    </geometry>
                    <material name="blue">
                            <color rgba=".20 .20 .100 1.0"/>
                    </material>
            </visual>
            <collision>
                    <origin xyz="0 0 0" rpy="0.000000 0.000000 0.000000"/>
                    <geometry>
                    <box size="0.0355 0.101 0.0356"/>
                    </geometry>
            </collision>
    </link>
    <link name="THORAX">
            <inertial>
              <origin xyz="0 0 0"/>
                    <mass value="25.000000"/>
                    <inertia ixx="1.259832"  ixy="0.030529"  ixz="-0.058400" iyx="0.030529"  iyy="6.565043" iyz="-0.026018"  izx="-0.058400"  izy="-0.026018"  izz="6.692983" />
            </inertial>
            <visual>
                    <origin xyz="0 0 0" rpy="0.0 0.0 0.0"/>
                    <geometry>
                    <box size="0.0355 0.101 0.0356"/>
                    </geometry>
                    <material name="blue">
                        <color rgba=".20 .20 .100 1.0"/>
                    </material>
            </visual>
            <collision>
                    <origin xyz="0 0 0" rpy="0.000000 0.000000 0.000000"/>
                    <geometry>
                    <box size="0.0355 0.101 0.0356"/>
                    </geometry>
            </collision>
    </link>
    <!-- LF_LEG LINKS -->
    <link name="LF_HIP">
            <inertial>
                    <origin xyz="0.02525 0 0"/>
                    <mass value="1.772000"/>
                    <inertia ixx=".0956126"  ixy="-.0000151" ixz="-.0110167"
                             iyx="-.0000151" iyy=".1012626"  iyz="-.0000229"
                             izx="-.0110167" izy="-.0000229" izz=".0006758" />
            </inertial>
            <visual>
                <origin xyz="0.02525 0 0"/>
                    <geometry>
                    <box size="0.0505 0.0355 0.0356"/>
                    </geometry>
                    <material name="Red">
                            <color rgba="1 0 0 1.0"/>
                    </material>
            </visual>
            <collision>
            <origin xyz="0.02525 0 0"/>
                    <geometry>
                    <box size="0.0505 0.0355 0.0356"/>
                    </geometry>
            </collision>
    </link>
    <link name="LF_ULEG">
            <inertial>
            <origin xyz="0.02525 0 0"/>
                    <inertia ixx=".0027712"  ixy=".0054381"  ixz=".000002"
                             iyx=".0054381"  iyy=".0694937"  iyz="0.0"
                             izx=".000002"   izy="0.0"       izz=".07045" />
                    <mass value="1.772"/>
            </inertial>
            <visual>
            <origin xyz="0.02525 0 0"/>
                    <geometry>
                    <box size="0.0505 0.0355 0.0356"/>
                    </geometry>
                    <material name="Red">
                    </material>
            </visual>
            <collision>
            <origin xyz="0.02525 0 0"/>
                    <geometry>
                    <box size="0.0505 0.0355 0.0356"/>
                    </geometry>
            </collision>
    </link>
    <link name="LF_LLEG">
            <inertial>
            <origin xyz="0.04 0 0"/>
                    <mass value="1.600000"/>
                    <inertia ixx="0.000423"  ixy="-0.000003" ixz="0.000000" iyx="-0.000003"  iyy="0.022033" iyz="0.000000"  izx="0.000000"  izy="0.000000"  izz="0.021843" />
            </inertial>
            <visual>
            <origin xyz="0.04 0 0"/>
                    <geometry>
                    <box size="0.08 0.01 0.01"/>
                    </geometry>
                    <material name="Red">
                    </material>
            </visual>
            <collision>
            <origin xyz="0.04 0 0"/>
                    <geometry>
                    <box size="0.08 0.01 0.01"/>
                    </geometry>
            </collision>
    </link>

    <!-- RF_LEG LINKS -->
    <link name="RF_HIP">
            <inertial>
            <origin xyz="0.02525 0 0"/>
                    <mass value="1.772000"/>
                    <inertia ixx="0.002771"  ixy="0.005438" ixz="0.000000" iyx="0.005438"  iyy="0.069494" iyz="0.000000"  izx="0.000000"  izy="0.000000"  izz="0.070450" />
            </inertial>
            <visual>
            <origin xyz="0.02525 0 0"/>
                    <geometry>
                    <box size="0.0505 0.0355 0.0356"/>
                    </geometry>
                    <material name="Red">
                    </material>
            </visual>
            <collision>
            <origin xyz="0.02525 0 0"/>
                    <geometry>
                    <box size="0.0505 0.0355 0.0356"/>
                    </geometry>
            </collision>
    </link>
    <link name="RF_ULEG">
            <inertial>
            <origin xyz="0.02525 0 0"/>
                    <mass value="2.482000"/>
                    <inertia ixx="0.095613"  ixy="0.000015" ixz="0.011017" iyx="0.000015"  iyy="0.101263" iyz="-0.000023"  izx="0.011017"  izy="-0.000023"  izz="0.000676" />
            </inertial>
            <visual>
            <origin xyz="0.02525 0 0"/>
                    <geometry>
                    <box size="0.0505 0.0355 0.0356"/>
                    </geometry>
                    <material name="Red">
                    </material>
            </visual>
            <collision>
            <origin xyz="0.02525 0 0"/>
                    <geometry>
                    <box size="0.0505 0.0355 0.0356"/>
                    </geometry>
            </collision>
    </link>
    <link name="RF_LLEG">
            <inertial>
            <origin xyz="0.04 0 0"/>
                    <mass value="1.600000"/>
                    <inertia ixx="0.000423"  ixy="-0.000003" ixz="0.000000" iyx="-0.000003"  iyy="0.022033" iyz="0.000000"  izx="0.000000"  izy="0.000000"  izz="0.021843" />
            </inertial>
            <visual>
            <origin xyz="0.04 0 0"/>
                    <geometry>
                    <box size="0.08 0.01 0.01"/>
                    </geometry>
                    <material name="Red">
                    </material>
            </visual>
            <collision>
            <origin xyz="0.04 0 0"/>
                    <geometry>
                    <box size="0.08 0.01 0.01"/>
                    </geometry>
            </collision>
    </link>
    <!-- LH_LEG LINKS -->
    <link name="LH_HIP">
            <inertial>
            <origin xyz="0.02525 0 0"/>
                    <mass value="1.772000"/>
                    <inertia ixx="0.002771"  ixy="-0.005438" ixz="-0.000000" iyx="-0.005438"  iyy="0.069494" iyz="0.000000"  izx="-0.000000"  izy="0.000000"  izz="0.070450" />
            </inertial>
            <visual>
            <origin xyz="0.02525 0 0"/>
                    <geometry>
                    <box size="0.0505 0.0355 0.0356"/>
                    </geometry>
                    <material name="Red">
                    </material>
            </visual>
            <collision>
            <origin xyz="0.02525 0 0"/>
                    <geometry>
                    <box size="0.0505 0.0355 0.0356"/>
                    </geometry>
            </collision>
    </link>
    <link name="LH_ULEG">
            <inertial>
            <origin xyz="0.02525 0 0"/>
                    <mass value="2.482000"/>
                    <inertia ixx="0.095613"  ixy="0.000015" ixz="0.011017" iyx="0.000015"  iyy="0.101263" iyz="-0.000023"  izx="0.011017"  izy="-0.000023"  izz="0.000676" />
            </inertial>
            <visual>
            <origin xyz="0.02525 0 0"/>
                    <geometry>
                    <box size="0.0505 0.0355 0.0356"/>
                    </geometry>
                    <material name="Red">
                    </material>
            </visual>
            <collision>
            <origin xyz="0.02525 0 0"/>
                    <geometry>
                    <box size="0.0505 0.0355 0.0356"/>
                    </geometry>
            </collision>
    </link>
    <link name="LH_LLEG">
            <inertial>
            <origin xyz="0.04 0 0"/>
                    <mass value="1.600000"/>
                    <inertia ixx="0.000423"  ixy="0.000003" ixz="0.000000" iyx="0.000003"  iyy="0.022033" iyz="0.000000"  izx="0.000000"  izy="0.000000"  izz="0.021843" />
            </inertial>
            <visual>
            <origin xyz="0.04 0 0"/>
                    <geometry>
                    <box size="0.08 0.01 0.01"/>
                    </geometry>
                    <material name="Red">
                    </material>
            </visual>
            <collision>
            <origin xyz="0.04 0 0"/>
                    <geometry>
                    <box size="0.08 0.01 0.01"/>
                    </geometry>
            </collision>
    </link>
    <!-- RH_LEG LINKS -->
    <link name="RH_HIP">
            <inertial>
            <origin xyz="0.02525 0 0"/>
                    <mass value="1.772000"/>
                    <inertia ixx="0.002771"  ixy="-0.005438" ixz="-0.000000" iyx="-0.005438"  iyy="0.069494" iyz="0.000000"  izx="-0.000000"  izy="0.000000"  izz="0.070450" />
            </inertial>
            <visual>
            <origin xyz="0.02525 0 0"/>
                    <geometry>
                    <box size="0.0505 0.0355 0.0356"/>
                    </geometry>
                    <material name="Red">
                    </material>
            </visual>
            <collision>
            <origin xyz="0.02525 0 0"/>
                    <geometry>
                    <box size="0.0505 0.0355 0.0356"/>
                    </geometry>
            </collision>
    </link>
    <link name="RH_ULEG">
            <inertial>
            <origin xyz="0.02525 0 0"/>
                    <mass value="2.482000"/>
                    <inertia ixx="0.095613"  ixy="-0.000015" ixz="-0.011017" iyx="-0.000015"  iyy="0.101263" iyz="-0.000023"  izx="-0.011017"  izy="-0.000023"  izz="0.000676" />
            </inertial>
            <visual>
            <origin xyz="0.02525 0 0"/>
                    <geometry>
                    <box size="0.0505 0.0355 0.0356"/>
                    </geometry>
                    <material name="Red">
                    </material>
            </visual>
            <collision>
            <origin xyz="0.02525 0 0"/>
                    <geometry>
                    <box size="0.0505 0.0355 0.0356"/>
                    </geometry>
            </collision>
    </link>
    <link name="RH_LLEG">
            <inertial>
                    <origin xyz="0.04 0 0"/>
                    <mass value="1.600000"/>
                    <inertia ixx="0.000423"  ixy="0.000003" ixz="0.000000" iyx="0.000003"  iyy="0.022033" iyz="0.000000"  izx="0.000000"  izy="0.000000"  izz="0.021843" />
            </inertial>
            <visual>
            <origin xyz="0.04 0 0"/>
                    <geometry>
                    <box size="0.08 0.01 0.01"/>
                    </geometry>
                    <material name="Red">
                    </material>
            </visual>
            <collision>
            <origin xyz="0.04 0 0"/>
                    <geometry>
                    <box size="0.08 0.01 0.01"/>
                    </geometry>
            </collision>
    </link>
<!-- ROBOT JOINTS -->
    <joint name="BODY_JOINT" type="continuous">
            <origin xyz="-0.0505 0.0 0.0" rpy="0.0 0.0 3.1415"/>
            <parent link="ABDOMEN"/>
            <child link="THORAX"/>
            <axis xyz="0 1 0"/>
    </joint>

   <!-- LF_LEG JOINTS -->
   <joint name="LF_HIP_AA" type="continuous">
           <origin xyz="0.0355 0.0505 0.0" rpy="0 0 0"/>
           <parent link="THORAX"/>
           <child link="LF_HIP"/>
           <axis xyz="1 0 0"/>
   </joint>
    <joint name="LF_HIP_FE" type="continuous">
            <origin xyz="0.0505 0.0 0.0" rpy="0 0 0.0"/>
            <parent link="LF_HIP"/>
            <child link="LF_ULEG"/>
            <axis xyz="0 1 0"/>
    </joint>
    <joint name="LF_LEG_FE" type="continuous">
            <origin xyz="0.0505 0.0 0.0" rpy="0.0 0.0 0.0"/>
            <parent link="LF_ULEG"/>
            <child link="LF_LLEG"/>
            <axis xyz="0 1 0"/>
    </joint>

    <!-- RF_LEG JOINTS -->
    <joint name="RF_HIP_AA" type="continuous">
            <origin xyz="0.0355 -0.0505 0.0" rpy="0 0 0"/>
            <parent link="THORAX"/>
            <child link="RF_HIP"/>
            <axis xyz="1 0 0"/>
    </joint>
    <joint name="RF_HIP_FE" type="continuous">
            <origin xyz="0.0505 0.0 0.0" rpy="0 0 0.0"/>
            <parent link="RF_HIP"/>
            <child link="RF_ULEG"/>
            <axis xyz="0 1 0"/>
    </joint>
    <joint name="RF_LEG_FE" type="continuous">
            <origin xyz="0.0505 0.0 0.0" rpy="0.0 0.0 0.0"/>
            <parent link="RF_ULEG"/>
            <child link="RF_LLEG"/>
            <axis xyz="0 1 0"/>
    </joint>

    <!-- LH_LEG JOINTS -->
    <joint name="LH_HIP_AA" type="continuous">
            <origin xyz="0.0355 0.0505 0.0" rpy="0 0 0.0"/>
            <parent link="ABDOMEN"/>
            <child link="LH_HIP"/>
            <axis xyz="1 0 0"/>
    </joint>
    <joint name="LH_HIP_FE" type="continuous">
            <origin xyz="0.0505 0.0 0.0" rpy="0 0 0.0"/>
            <parent link="LH_HIP"/>
            <child link="LH_ULEG"/>
            <axis xyz="0 1 0"/>
    </joint>
    <joint name="LH_LEG_FE" type="continuous">
            <origin xyz="0.0505 0.0 0.0" rpy="0.0 0.0 0.0"/>
            <parent link="LH_ULEG"/>
            <child link="LH_LLEG"/>
            <axis xyz="0 1 0"/>
    </joint>

    <!-- RH_LEG JOINTS -->
    <joint name="RH_HIP_AA" type="continuous">
            <origin xyz="0.0355 -0.0505 0.0" rpy="0.0 0.0 0.0"/>
            <parent link="ABDOMEN"/>
            <child link="RH_HIP"/>
            <axis xyz="1 0 0"/>
    </joint>
    <joint name="RH_HIP_FE" type="continuous">
            <origin xyz="0.0505 0.0 0.0" rpy="0 0 0"/>
            <parent link="RH_HIP"/>
            <child link="RH_ULEG"/>
            <axis xyz="0 1 0"/>
    </joint>
    <joint name="RH_LEG_FE" type="continuous">
            <origin xyz="0.0505 0.0 0.0" rpy="0 0.0 0.0"/>
            <parent link="RH_ULEG"/>
            <child link="RH_LLEG"/>
            <axis xyz="0 1 0"/>
    </joint>

 </robot>
