<?xml version="1.0" ?>
<sdf version='1.5'>
  <model name='ROBOT'>
    <plugin name="HopperPlugin" filename="libPacerGazeboPlugin.so"/>
    <link name='BODY'>
      <pose>0 0 0 0 0 0</pose>
      <inertial>
        <mass>10</mass>
        <inertia>
          <ixx>0.005833</ixx>
          <ixy>0.0</ixy>
          <ixz>-0.0</ixz>
          <iyy>0.003033</iyy>
          <iyz>-0.0</iyz>
          <izz>0.008633</izz>
        </inertia>
      </inertial>

      <visual name='BODY_visual'>
        <geometry>
          <box>
            <size>1 1 0.1</size>
          </box>
        </geometry>
      </visual>

      <collision name='BODY_collision'>
        <geometry>
          <box>
            <size>1 1 0.1</size>
          </box>
        </geometry>
      </collision>

    </link>

<!-- =============================== LF leg =============================== -->
    <joint name='LEG_XY_1' type='universal'>
      <pose>-0.0 0.0 0 0 0 0</pose>
      <parent>BODY0</parent>
      <child>LEG_1</child>
      <axis>
        <xyz>1 0 0</xyz>
        <limit>
          <lower>-1e+16</lower>
          <upper>1e+16</upper>
        </limit>
        <dynamics/>
      </axis>
      <axis2>
        <xyz>0 1 0</xyz>
        <limit>
          <lower>-1e+16</lower>
          <upper>1e+16</upper>
        </limit>
        <dynamics/>
      </axis2>
    </joint>


    <link name='LEG_1'>
      <pose>0 0 -0.25 0 0 0</pose>
      <inertial>
        <mass>1</mass>
        <inertia>
          <ixx>0.1</ixx>
          <ixy>0.0</ixy>
          <ixz>0.0</ixz>
          <iyy>0.1</iyy>
          <iyz>0.0</iyz>
          <izz>0.1</izz>
        </inertia>
      </inertial>

      <visual name='leg1_visual'>
        <geometry>
          <box>
            <size>0.05 0.05 0.5</size>
          </box>
        </geometry>
      </visual>

    </link>

    <joint name='LEG_Z_2' type='prismatic'>
      <pose>0.0 0 0 0 0 0</pose>
      <parent>LEG_1</parent>
      <child>LEG_2</child>
      <axis>
        <xyz>0 0 1</xyz>
        <limit>
          <lower>-1e+16</lower>
          <upper>1e+16</upper>
        </limit>
        <dynamics/>
      </axis>
    </joint>

    <link name='FOOT'>
      <pose>0 0 -1 0 0 0</pose>
      <inertial>
        <pose>0 0 0.25 0 0 0</pose>
        <mass>1</mass>
        <inertia>
          <ixx>0.1</ixx>
          <ixy>0.0</ixy>
          <ixz>0.0</ixz>
          <iyy>0.1</iyy>
          <iyz>0.0</iyz>
          <izz>0.1</izz>
        </inertia>
      </inertial>


      <visual name='leg2_visual'>
        <pose>0 0 0.25 0 0 0</pose>
        <geometry>
          <box>
            <size>0.025 0.025 0.5</size>
          </box>
        </geometry>
      </visual>

      <visual name='FOOT_visual'>
        <pose>0 0 0 0 0 0</pose>
        <geometry>
          <sphere>
            <radius>0.025</radius>
          </sphere>
        </geometry>
      </visual>

      <collision name='FOOT_collision'>
        <pose>0 0 0 0 0 0</pose>
        <geometry>
          <sphere>
            <radius>0.025</radius>
          </sphere>
        </geometry>
      </collision>

      <sensor name='FOOT_contact' type='contact'>
        <contact>
          <collision>FOOT_collision</collision>
        </contact>
        <update_rate>1000</update_rate>
      </sensor>
    </link>
  </model>
</sdf>
