<?xml version="1.0" ?>
<sdf version='1.5'>
  <model name='LINKS'>
    <plugin name="PacerPlugin" filename="libPacerGazeboPlugin.so"/>
    <plugin name="PacerPlugin" filename="libPacerGazeboPlugin.dylib"/>
    <pose>0 0 0.19 0 -0 0</pose>
    <link name='BODY0'>
      <pose>0 0 0 0 -0 0</pose>
      <inertial>
        <mass>3.6</mass>
        <inertia>
          <ixx>0.005833</ixx>
          <ixy>0.0</ixy>
          <ixz>-0.0</ixz>
          <iyy>0.003033</iyy>
          <iyz>-0.0</iyz>
          <izz>0.008633</izz>
        </inertia>
      </inertial>
      
      <visual name='BODY1_visual'>
        <pose>0.095 0 0 0 -0 0</pose>
        <geometry>
          <box>
            <size>0.04 0.125 0.04</size>
          </box>
        </geometry>
        <material>
          <ambient>0.2 0.2 0.2 1</ambient>
          <diffuse>0.5 0.5 0.5 1</diffuse>
          <specular>0.1 0.1 0.1 1</specular>
          <emissive>0 0 0 0</emissive>
        </material>
      <material>
        
      </material>
      </visual>
      <visual name='BODY0_visual'>
        <geometry>
          <box>
            <size>0.15 0.08 0.05</size>
          </box>
        </geometry>
        <material>
          <ambient>0.2 0.2 0.2 1</ambient>
          <diffuse>0.1 0.1 0.1 1</diffuse>
          <specular>0.1 0.1 0.1 1</specular>
          <emissive>0 0 0 0</emissive>
        </material>
      </visual>
      <visual name='BODYN_visual'>
        <pose>-0.095 0 0 0 -0 0</pose>
        <geometry>
          <box>
            <size>0.04 0.125 0.04</size>
          </box>
        </geometry>
        <material>
          <ambient>0.2 0.2 0.2 1</ambient>
          <diffuse>0.5 0.5 0.5 1</diffuse>
          <specular>0.1 0.1 0.1 1</specular>
          <emissive>0 0 0 0</emissive>
        </material>
      </visual>
      
      
      <collision name='BODY0_collision'>
        <geometry>
          <box>
            <size>0.15 0.08 0.05</size>
          </box>
        </geometry>
      </collision>
      
    </link>
    
    <!-- =============================== LF leg =============================== -->
    <joint name='LF_X_1' type='revolute'>
      <pose>0.0 0.0 0 0 0 0</pose>
      <parent>BODY0</parent>
      <child>LF_LEG_1</child>
      <axis>
        <xyz>1 0 0</xyz>
        <limit>
          <lower>-1e+16</lower>
          <upper>1e+16</upper>
        </limit>
        <dynamics/>
      </axis>
    </joint>
    
    
    <link name='LF_LEG_1'>
      <pose>0.115 0.05 0 0 0 0</pose>
      <inertial>
        <pose>0.020 0 0 0 0 0</pose>
        <mass>0.10</mass>
        <inertia>
          <ixx>1.5e-5</ixx>
          <ixy>0.0</ixy>
          <ixz>-0.0</ixz>
          <iyy>2.833e-5</iyy>
          <iyz>-0.0</iyz>
          <izz>2.833e-5</izz>
        </inertia>
      </inertial>
      
      <visual name='leg1_visual'>
        <pose>0.020 0 0 0 0 0</pose>
        <geometry>
          <box>
            <size>0.04 0.03 0.03</size>
          </box>
        </geometry>
        <material>
          <ambient>0.2 0.2 0.2 1</ambient>
          <diffuse>0.5 0.5 0.5 1</diffuse>
          <specular>0.1 0.1 0.1 1</specular>
          <emissive>0 0 0 0</emissive>
        </material>
      </visual>
      
    </link>
    
    <joint name='LF_Y_2' type='revolute'>
      <pose>0.0 0 0 0 0 0</pose>
      <parent>LF_LEG_1</parent>
      <child>LF_LEG_2</child>
      <axis>
        <xyz>0 1 0</xyz>
        <limit>
          <lower>-1e+16</lower>
          <upper>1e+16</upper>
        </limit>
        <dynamics/>
      </axis>
      
    </joint>
    
    <link name='LF_LEG_2'>
      <pose>0.155 0.05 0 0 0 0</pose>
      <inertial>
        <mass>0.10</mass>
        <inertia>
          <ixx>1.083e-5</ixx>
          <ixy>0.0</ixy>
          <ixz>-0.0</ixz>
          <iyy>0.0001233</iyy>
          <iyz>-0.0</iyz>
          <izz>0.001275</izz>
        </inertia>
      </inertial>
      
      <visual name='leg2_visual'>
        <pose>0.0395 0 0 0 0 0</pose>
        <geometry>
          <box>
            <size>0.1 0.03 0.02</size>
          </box>
        </geometry>
        <material>
          <ambient>0.2 0.2 0.2 1</ambient>
          <diffuse>1 0.5 0   1</diffuse>
          <specular>0.1 0.1 0.1 1</specular>
          <emissive>0 0 0 0</emissive>
        </material>
      </visual>
      
    </link>
    
    <joint name='LF_Y_3' type='revolute'>
      <pose>-0.129 0 0 0 0 0</pose>
      <parent>LF_LEG_2</parent>
      <child>LF_FOOT</child>
      <axis>
        <xyz>0 1 0</xyz>
        <limit>
          <lower>-1e+16</lower>
          <upper>1e+16</upper>
        </limit>
        <dynamics/>
      </axis>
      
    </joint>
    
    <link name='LF_FOOT'>
      <pose>0.361 0.05 0 0 0 0</pose>
      <inertial>
        <pose>-0.0645 0 0 0 0 0</pose>
        <mass>0.10</mass>
        <inertia>
          <ixx>5e-7</ixx>
          <ixy>-1.215e-10</ixy>
          <ixz>-0.0</ixz>
          <iyy>3.358e-5</iyy>
          <iyz>-0.0</iyz>
          <izz>3.358e-5</izz>
        </inertia>
      </inertial>
      
      <visual name='leg3_visual'>
        <pose>-0.0645 0 0 0 1.579 0</pose>
        <geometry>
          <cylinder>
            <radius>0.005</radius>
            <length>0.129</length>
          </cylinder>
        </geometry>
        <material>
          <ambient>0.2 0.2 0.2 1</ambient>
          <diffuse>0.9 0.9 0.9   1</diffuse>
          <specular>0.1 0.1 0.1 1</specular>
          <emissive>0 0 0 0</emissive>
        </material>
      </visual>
      
      <visual name='LF_FOOT_visual'>
        <pose>0 0 0 0 0 0</pose>
        <geometry>
          <sphere>
            <radius>0.01</radius>
          </sphere>
        </geometry>
<!--        <material>-->
<!--          <ambient>0.2 0.2 0.2 1</ambient>-->
<!--          <diffuse>0 0 0 0</diffuse>-->
<!--          <specular>0.1 0.1 0.1 1</specular>-->
<!--          <emissive>0 0 0 0</emissive>-->
<!--        </material>-->
      </visual>
      
      <collision name='LF_FOOT_collision'>
        <pose>0 0 0 0 0 0</pose>
        <geometry>
          <sphere>
            <radius>0.01</radius>
          </sphere>
        </geometry>
        <surface>
          <restitution_coefficient>0</restitution_coefficient>
          <friction>
            <ode>
              <mu>100</mu>
              <mu2>100</mu2>
            </ode>
          </friction>
        </surface>
      </collision>
      
      <sensor name='LF_FOOT_contact' type='contact'>
        <contact>
          <collision>LF_FOOT_collision</collision>
        </contact>
        <update_rate>1000</update_rate>
      </sensor>
    </link>
    
    <!-- =============================== RF leg =============================== -->
    <joint name='RF_X_1' type='revolute'>
      <pose>-0.025 0 0 0 0 0</pose>
      <parent>BODY0</parent>
      <child>RF_LEG_1</child>
      <axis>
        <xyz>1 0 0</xyz>
        <limit>
          <lower>-1e+16</lower>
          <upper>1e+16</upper>
        </limit>
        <dynamics/>
      </axis>
      
    </joint>
    
    
    <link name='RF_LEG_1'>
      <pose>0.115 -0.05 0 0 0 0</pose>
      <inertial>
        <mass>0.10</mass>
        <inertia>
          <ixx>1.5e-5</ixx>
          <ixy>0.0</ixy>
          <ixz>-0.0</ixz>
          <iyy>2.833e-5</iyy>
          <iyz>-0.0</iyz>
          <izz>2.833e-5</izz>
        </inertia>
      </inertial>
      
      <visual name='leg1_visual'>
        <pose>0.020 0 0 0 0 0</pose>
        <geometry>
          <box>
            <size>0.04 0.03 0.03</size>
          </box>
        </geometry>
        <material>
          <ambient>0.2 0.2 0.2 1</ambient>
          <diffuse>0.5 0.5 0.5 1</diffuse>
          <specular>0.1 0.1 0.1 1</specular>
          <emissive>0 0 0 0</emissive>
        </material>
      </visual>
    </link>
    
    <joint name='RF_Y_2' type='revolute'>
      <pose>0.0 0 0 0 0 0</pose>
      <parent>RF_LEG_1</parent>
      <child>RF_LEG_2</child>
      <axis>
        <xyz>0 -1 0</xyz>
        <limit>
          <lower>-1e+16</lower>
          <upper>1e+16</upper>
        </limit>
        <dynamics/>
      </axis>
    </joint>
    
    <link name='RF_LEG_2'>
      <pose>0.155 -0.05 0 0 0 0</pose>
      <inertial>
        <mass>0.10</mass>
        <inertia>
          <ixx>1.083e-5</ixx>
          <ixy>0.0</ixy>
          <ixz>-0.0</ixz>
          <iyy>0.0001233</iyy>
          <iyz>-0.0</iyz>
          <izz>0.001275</izz>
        </inertia>
      </inertial>
      
      <visual name='leg2_visual'>
        <pose>0.0395 0 0 0 0 0</pose>
        <geometry>
          <box>
            <size>0.1 0.03 0.02</size>
          </box>
        </geometry>
        <material>
          <ambient>0.2 0.2 0.2 1</ambient>
          <diffuse>1 0.5 0   1</diffuse>
          <specular>0.1 0.1 0.1 1</specular>
          <emissive>0 0 0 0</emissive>
        </material>
      </visual>
      
    </link>
    
    <joint name='RF_Y_3' type='revolute'>
      <pose>-0.129 0 0 0 0 0</pose>
      <parent>RF_LEG_2</parent>
      <child>RF_FOOT</child>
      <axis>
        <xyz>0 -1 0</xyz>
        <limit>
          <lower>-1e+16</lower>
          <upper>1e+16</upper>
        </limit>
        <dynamics/>
      </axis>
    </joint>
    
    <link name='RF_FOOT'>
      <pose>0.361 -0.05 0 0 0 0</pose>
      <inertial>
        <pose>-0.0645 0 0 0 0 0</pose>
        <mass>0.10</mass>
        <inertia>
          <ixx>5e-7</ixx>
          <ixy>-1.215e-10</ixy>
          <ixz>-0.0</ixz>
          <iyy>3.358e-5</iyy>
          <iyz>-0.0</iyz>
          <izz>3.358e-5</izz>
        </inertia>
      </inertial>
      
      <visual name='leg3_visual'>
        <pose>-0.0645 0 0 0 1.579 0</pose>
        <geometry>
          <cylinder>
            <radius>0.005</radius>
            <length>0.129</length>
          </cylinder>
        </geometry>
        <material>
          <ambient>0.2 0.2 0.2 1</ambient>
          <diffuse>0.9 0.9 0.9   1</diffuse>
          <specular>0.1 0.1 0.1 1</specular>
          <emissive>0 0 0 0</emissive>
        </material>
      </visual>
      
      <visual name='RF_FOOT_visual'>
        <pose>0 0 0 0 0 0</pose>
        <geometry>
          <sphere>
            <radius>0.01</radius>
          </sphere>
        </geometry>
      </visual>
      
      <collision name='RF_FOOT_collision'>
        <pose>0 0 0 0 0 0</pose>
        <geometry>
          <sphere>
            <radius>0.01</radius>
          </sphere>
        </geometry>
        <surface>
          <restitution_coefficient>0</restitution_coefficient>
          <friction>
            <ode>
              <mu>100</mu>
              <mu2>100</mu2>
            </ode>
          </friction>
        </surface>
      </collision>
      
      <sensor name='RF_FOOT_contact' type='contact'>
        <contact>
          <collision>RF_FOOT_collision</collision>
        </contact>
        <update_rate>1000</update_rate>
      </sensor>
    </link>
    
    <!-- =============================== LH leg =============================== -->
    <joint name='LH_X_1' type='revolute'>
      <pose>0.0 0 0 0 0 0</pose>
      <parent>BODY0</parent>
      <child>LH_LEG_1</child>
      <axis>
        <xyz>-1 0 0</xyz>
        <limit>
          <lower>-1e+16</lower>
          <upper>1e+16</upper>
        </limit>
        <dynamics/>
      </axis>
      
    </joint>
    
    <link name='LH_LEG_1'>
      <pose>-0.115 0.05 0 0 0 0</pose>
      <inertial>
        <pose>-0.0255 0 0 0 0 0</pose>
        <mass>0.10</mass>
        <inertia>
          <ixx>1.5e-5</ixx>
          <ixy>0.0</ixy>
          <ixz>-0.0</ixz>
          <iyy>2.833e-5</iyy>
          <iyz>-0.0</iyz>
          <izz>2.833e-5</izz>
        </inertia>
      </inertial>
      
      <visual name='leg1_visual'>
        <pose>-0.0255 0 0 0 0 0</pose>
        <geometry>
          <box>
            <size>0.051 0.03 0.03</size>
          </box>
        </geometry>
        <material>
          <ambient>0.2 0.2 0.2 1</ambient>
          <diffuse>0.5 0.5 0.5 1</diffuse>
          <specular>0.1 0.1 0.1 1</specular>
          <emissive>0 0 0 0</emissive>
        </material>
      </visual>
    </link>
    
    <joint name='LH_Y_2' type='revolute'>
      <pose>0 0 0 0 0 0</pose>
      <parent>LH_LEG_1</parent>
      <child>LH_LEG_2</child>
      <axis>
        <xyz>0 1 0</xyz>
        <limit>
          <lower>-1e+16</lower>
          <upper>1e+16</upper>
        </limit>
        <dynamics/>
      </axis>
      
    </joint>
    
    <link name='LH_LEG_2'>
      <pose>-0.166 0.05 0 0 0 0</pose>
      <inertial>
        <pose>-0.0385 0 0 0 0 0</pose>
        <mass>0.10</mass>
        <inertia>
          <ixx>1.083e-5</ixx>
          <ixy>0.0</ixy>
          <ixz>-0.0</ixz>
          <iyy>0.0001233</iyy>
          <iyz>-0.0</iyz>
          <izz>0.001275</izz>
        </inertia>
      </inertial>
      
      <visual name='leg2_visual'>
        <pose>-0.0385 0 0 0 0 0</pose>
        <geometry>
          <box>
            <size>0.1 0.03 0.02</size>
          </box>
        </geometry>
        <material>
          <ambient>0.2 0.2 0.2 1</ambient>
          <diffuse>1 0.5 0   1</diffuse>
          <specular>0.1 0.1 0.1 1</specular>
          <emissive>0 0 0 0</emissive>
        </material>
      </visual>
      
    </link>
    
    <joint name='LH_Y_3' type='revolute'>
      <pose>0.129 0 0 0 0 0</pose>
      <parent>LH_LEG_2</parent>
      <child>LH_FOOT</child>
      <axis>
        <xyz>0 1 0</xyz>
        <limit>
          <lower>-1e+16</lower>
          <upper>1e+16</upper>
        </limit>
        <dynamics/>
      </axis>
      
    </joint>
    
    <link name='LH_FOOT'>
      <pose>-0.372 0.05 0 0 0 0</pose>
      <inertial>
        <pose>0.0645 0 0 0 0 0</pose>
        <mass>0.10</mass>
        <inertia>
          <ixx>5e-7</ixx>
          <ixy>-1.215e-10</ixy>
          <ixz>-0.0</ixz>
          <iyy>3.358e-5</iyy>
          <iyz>-0.0</iyz>
          <izz>3.358e-5</izz>
        </inertia>
      </inertial>
      
      <visual name='leg3_visual'>
        <pose>0.0645 0 0 0 1.579 0</pose>
        <geometry>
          <cylinder>
            <radius>0.005</radius>
            <length>0.129</length>
          </cylinder>
        </geometry>
        <material>
          <ambient>0.2 0.2 0.2 1</ambient>
          <diffuse>0.9 0.9 0.9   1</diffuse>
          <specular>0.1 0.1 0.1 1</specular>
          <emissive>0 0 0 0</emissive>
        </material>
      </visual>
      
      <visual name='LH_FOOT_visual'>
        <pose>0 0 0 0 0 0</pose>
        <geometry>
          <sphere>
            <radius>0.01</radius>
          </sphere>
        </geometry>
      </visual>
      
      <collision name='LH_FOOT_collision'>
        <pose>0 0 0 0 0 0</pose>
        <geometry>
          <sphere>
            <radius>0.01</radius>
          </sphere>
        </geometry>
        <surface>
          <restitution_coefficient>0</restitution_coefficient>
          <friction>
            <ode>
              <mu>100</mu>
              <mu2>100</mu2>
            </ode>
          </friction>
        </surface>
      </collision>
      
      <sensor name='LH_FOOT_contact' type='contact'>
        <contact>
          <collision>LH_FOOT_collision</collision>
        </contact>
        <update_rate>1000</update_rate>
      </sensor>
    </link>
    
    <!-- =============================== RH leg =============================== -->
    <joint name='RH_X_1' type='revolute'>
      <pose>0 0 0 0 0 0</pose>
      <parent>BODY0</parent>
      <child>RH_LEG_1</child>
      <axis>
        <xyz>-1 0 0</xyz>
        <limit>
          <lower>-1e+16</lower>
          <upper>1e+16</upper>
        </limit>
        <dynamics/>
      </axis>
    </joint>
    
    <link name='RH_LEG_1'>
      <pose>-0.115 -0.05 0 0 0 0</pose>
      <inertial>
        <pose>-0.0255 0 0 0 0 0</pose>
        <mass>0.10</mass>
        <inertia>
          <ixx>1.5e-5</ixx>
          <ixy>0.0</ixy>
          <ixz>-0.0</ixz>
          <iyy>2.833e-5</iyy>
          <iyz>-0.0</iyz>
          <izz>2.833e-5</izz>
        </inertia>
      </inertial>
      
      <visual name='leg1_visual'>
        <pose>-0.0255 0 0 0 0 0</pose>
        <geometry>
          <box>
            <size>0.051 0.03 0.03</size>
          </box>
        </geometry>
        <material>
          <ambient>0.2 0.2 0.2 1</ambient>
          <diffuse>0.5 0.5 0.5 1</diffuse>
          <specular>0.1 0.1 0.1 1</specular>
          <emissive>0 0 0 0</emissive>
        </material>
      </visual>
      
    </link>
    
    <joint name='RH_Y_2' type='revolute'>
      <pose>0 0 0 0 0 0</pose>
      <parent>RH_LEG_1</parent>
      <child>RH_LEG_2</child>
      <axis>
        <xyz>0 -1 0</xyz>
        <limit>
          <lower>-1e+16</lower>
          <upper>1e+16</upper>
        </limit>
        <dynamics/>
      </axis>
      
    </joint>
    
    <link name='RH_LEG_2'>
      <pose>-0.166 -0.05 0 0 0 0</pose>
      <inertial>
        <pose>-0.0385 0 0 0 0 0</pose>
        <mass>0.10</mass>
        <inertia>
          <ixx>1.083e-5</ixx>
          <ixy>0.0</ixy>
          <ixz>-0.0</ixz>
          <iyy>0.0001233</iyy>
          <iyz>-0.0</iyz>
          <izz>0.001275</izz>
        </inertia>
      </inertial>
      
      <visual name='leg2_visual'>
        <pose>-0.0385 0 0 0 0 0</pose>
        <geometry>
          <box>
            <size>0.1 0.03 0.02</size>
          </box>
        </geometry>
        <material>
          <ambient>0.2 0.2 0.2 1</ambient>
          <diffuse>1 0.5 0   1</diffuse>
          <specular>0.1 0.1 0.1 1</specular>
          <emissive>0 0 0 0</emissive>
        </material>
      </visual>
      
    </link>
    
    <joint name='RH_Y_3' type='revolute'>
      <pose>0.129 0 0 0 0 0</pose>
      <parent>RH_LEG_2</parent>
      <child>RH_FOOT</child>
      <axis>
        <xyz>0 -1 0</xyz>
        <limit>
          <lower>-1e+16</lower>
          <upper>1e+16</upper>
        </limit>
        <dynamics/>
      </axis>
      
    </joint>
    
    
    <link name='RH_FOOT'>
      <pose>-0.372 -0.05 0 0 0 0</pose>
      <inertial>
        <pose>0.0645 0 0 0 0 0</pose>
        <mass>0.10</mass>
        <inertia>
          <ixx>5e-7</ixx>
          <ixy>-1.215e-10</ixy>
          <ixz>-0.0</ixz>
          <iyy>3.358e-5</iyy>
          <iyz>-0.0</iyz>
          <izz>3.358e-5</izz>
        </inertia>
      </inertial>
      
      <visual name='leg3_visual'>
        <pose>0.0645 0 0 0 1.579 0</pose>
        <geometry>
          <cylinder>
            <radius>0.005</radius>
            <length>0.129</length>
          </cylinder>
        </geometry>
        <material>
          <ambient>0.2 0.2 0.2 1</ambient>
          <diffuse>0.9 0.9 0.9   1</diffuse>
          <specular>0.1 0.1 0.1 1</specular>
          <emissive>0 0 0 0</emissive>
        </material>
      </visual>
      
      <visual name='RH_FOOT_visual'>
        <pose>0 0 0 0 0 0</pose>
        <geometry>
          <sphere>
            <radius>0.01</radius>
          </sphere>
        </geometry>
      </visual>
      
      <collision name='RH_FOOT_collision'>
        <pose>0 0 0 0 0 0</pose>
        <geometry>
          <sphere>
            <radius>0.01</radius>
          </sphere>
        </geometry>
        <surface>
          <restitution_coefficient>0</restitution_coefficient>
          <friction>
            <ode>
              <mu>100</mu>
              <mu2>100</mu2>
            </ode>
          </friction>
        </surface>
      </collision>
      
      <sensor name='RH_FOOT_contact' type='contact'>
        <contact>
          <collision>RH_FOOT_collision</collision>
        </contact>
        <update_rate>1000</update_rate>
      </sensor>
    </link>
  </model>
</sdf>
