<?xml version="1.0" ?>
<!-- =================================================================================== -->
<!-- |    This document was autogenerated by xacro from /Users/joshualurz/models/human/models/human//human.xacro | -->
<!-- |    EDITING THIS FILE BY HAND IS NOT RECOMMENDED                                 | -->
<!-- =================================================================================== -->
<sdf version="1.4">
  <model name="human">
  <plugin name="PacerPlugin" filename="libPacerGazeboPlugin.so"/>
    <!-- TODO: These should not be needed but parameters aren't working -->
    <static>false</static>
    <link name="trunk">
      <pose>0.0 0.0 1.051 0.0 0.0 0.0</pose>
      <!-- Height of leg + thigh + 0.5 * trunk-->
      <inertial>
        <mass>37.0762</mass>
        <pose>0.0 0.0 0.0 0.0 0.0 0.0</pose>
        <!-- Link mass is centered -->
        <inertia>
          <ixx>1.674614776</ixx>
          <ixy>0.0</ixy>
          <ixz>0.0</ixz>
          <iyz>0.0</iyz>
          <iyy>0.01679029</iyy>
          <izz>1.674614776</izz>
        </inertia>
      </inertial>
      <collision name="collision">
        <geometry>
          <cylinder>
            <length>0.376</length>
            <radius>0.02</radius>
          </cylinder>
        </geometry>
      </collision>
      <visual name="visual">
        <geometry>
          <cylinder>
            <length>0.376</length>
            <radius>0.02</radius>
          </cylinder>
        </geometry>
      </visual>
      <sensor name="trunk_contact" type="contact">
        <contact>
          <collision>collision</collision>
        </contact>
      </sensor>
    </link>
    <link name="right_foot">
      <pose>0.041 -0.0855 0.02 0.0 1.570796327 0.0</pose>
      <!-- Move forward by half length of foot. Y coordinate is half the pelvic width. Rotate to horizontal plane -->
      <inertial>
        <mass>1.0817</mass>
        <pose>0.0 0.0 0.0 0.0 0.0 0.0</pose>
        <!-- Link mass is centered -->
        <inertia>
          <ixx>0.00164105</ixx>
          <iyy>0.000227357</iyy>
          <izz>0.00164105</izz>
          <ixy>0.0</ixy>
          <ixz>0.0</ixz>
          <iyz>0.0</iyz>
        </inertia>
      </inertial>
      <collision name="collision">
        <geometry>
          <cylinder>
            <length>0.082</length>
            <radius>0.02</radius>
          </cylinder>
        </geometry>
        <surface>
          <friction>
            <ode>
              <mu>1.0</mu>
              <mu2>1.0</mu2>
            </ode>
          </friction>
        </surface>
      </collision>
      <visual name="visual">
        <geometry>
          <cylinder>
            <length>0.082</length>
            <radius>0.02</radius>
          </cylinder>
        </geometry>
      </visual>
      <sensor name="right_foot_contact" type="contact">
        <contact>
          <collision>collision</collision>
        </contact>
      </sensor>
    </link>
    <joint name="right_ankle" type="revolute">
      <parent>right_leg</parent>
      <child>right_foot</child>
      <pose>0.0 0.0 -0.041 0.0 -1.570796327 0.0</pose>
      <axis>
        <xyz>0.0 1 0.0</xyz>
        <limit>
          <lower>-0.680678408</lower>
          <upper>0.726056969</upper>
        </limit>
        <dynamics>
          <damping>0.05</damping>
        </dynamics>
      </axis>
    </joint>
    <link name="left_foot">
      <pose>0.041 0.0855 0.02 0.0 1.570796327 0.0</pose>
      <!-- Move forward by half length of foot. Y coordinate is half the pelvic width. Rotate to horizontal plane -->
      <inertial>
        <mass>1.0817</mass>
        <pose>0.0 0.0 0.0 0.0 0.0 0.0</pose>
        <!-- Link mass is centered -->
        <inertia>
          <ixx>0.00164105</ixx>
          <iyy>0.000227357</iyy>
          <izz>0.00164105</izz>
          <ixy>0.0</ixy>
          <ixz>0.0</ixz>
          <iyz>0.0</iyz>
        </inertia>
      </inertial>
      <collision name="collision">
        <geometry>
          <cylinder>
            <length>0.082</length>
            <radius>0.02</radius>
          </cylinder>
        </geometry>
        <surface>
          <friction>
            <ode>
              <mu>1.0</mu>
              <mu2>1.0</mu2>
            </ode>
          </friction>
        </surface>
      </collision>
      <visual name="visual">
        <geometry>
          <cylinder>
            <length>0.082</length>
            <radius>0.02</radius>
          </cylinder>
        </geometry>
      </visual>
      <sensor name="left_foot_contact" type="contact">
        <contact>
          <collision>collision</collision>
        </contact>
      </sensor>
    </link>
    <joint name="left_ankle" type="revolute">
      <parent>left_leg</parent>
      <child>left_foot</child>
      <pose>0.0 0.0 -0.041 0.0 -1.570796327 0.0</pose>
      <axis>
        <xyz>0.0 1 0.0</xyz>
        <limit>
          <lower>-0.680678408</lower>
          <upper>0.726056969</upper>
        </limit>
        <dynamics>
          <damping>0.05</damping>
        </dynamics>
      </axis>
    </joint>
    <link name="right_leg">
      <pose>0.0 -0.0855 0.2245 0.0 0.0 0.0</pose>
      <!-- Y coordinate is half the pelvic width. Z coordinate is half the leg height. -->
      <inertial>
        <mass>3.4689</mass>
        <pose>0.0 0.0 0.027403 0.0 0.0 0.0</pose>
        <inertia>
          <ixx>0.052923954</ixx>
          <iyy>0.000276446</iyy>
          <izz>0.052923954</izz>
          <ixy>0.0</ixy>
          <ixz>0.0</ixz>
          <iyz>0.0</iyz>
        </inertia>
      </inertial>
      <collision name="collision">
        <geometry>
          <cylinder>
            <length>0.409</length>
            <radius>0.02</radius>
          </cylinder>
        </geometry>
      </collision>
      <visual name="visual">
        <geometry>
          <cylinder>
            <length>0.409</length>
            <radius>0.02</radius>
          </cylinder>
        </geometry>
      </visual>
      <sensor name="right_leg_contact" type="contact">
        <contact>
          <collision>collision</collision>
        </contact>
      </sensor>
    </link>
    <joint name="right_knee" type="revolute">
      <parent>right_thigh</parent>
      <child>right_leg</child>
      <pose>0.0 0.0 0.2045 0.0 0.0 0.0</pose>
      <axis>
        <xyz>0.0 1 0.0</xyz>
        <limit>
          <lower>0</lower>
          <upper>2.160717614</upper>
        </limit>
        <dynamics>
          <damping>0.05</damping>
        </dynamics>
      </axis>
    </joint>
    <link name="left_leg">
      <pose>0.0 0.0855 0.2245 0.0 0.0 0.0</pose>
      <!-- Y coordinate is half the pelvic width. Z coordinate is half the leg height -->
      <inertial>
        <mass>3.4689</mass>
        <pose>0.0 0.0 0.027403 0.0 0.0 0.0</pose>
        <inertia>
          <ixx>0.052923954</ixx>
          <iyy>0.000276446</iyy>
          <izz>0.052923954</izz>
          <ixy>0.0</ixy>
          <ixz>0.0</ixz>
          <iyz>0.0</iyz>
        </inertia>
      </inertial>
      <collision name="collision">
        <geometry>
          <cylinder>
            <length>0.409</length>
            <radius>0.02</radius>
          </cylinder>
        </geometry>
      </collision>
      <visual name="visual">
        <geometry>
          <cylinder>
            <length>0.409</length>
            <radius>0.02</radius>
          </cylinder>
        </geometry>
      </visual>
      <sensor name="left_leg_contact" type="contact">
        <contact>
          <collision>collision</collision>
        </contact>
      </sensor>
    </link>
    <joint name="left_knee" type="revolute">
      <parent>left_thigh</parent>
      <child>left_leg</child>
      <pose>0.0 0.0 0.2045 0.0 0.0 0.0</pose>
      <axis>
        <xyz>0.0 1 0.0</xyz>
        <limit>
          <lower>0</lower>
          <upper>2.160717614</upper>
        </limit>
        <dynamics>
          <damping>0.05</damping>
        </dynamics>
      </axis>
    </joint>
    <link name="right_thigh">
      <pose>0.0 -0.0855 0.646 0.0 0.0 0.0</pose>
      <!-- Y coordinate is half the pelvic width. X coordinate is the leg height + 0.5 * thigh height -->
      <inertial>
        <mass>7.46</mass>
        <pose>0.0 0.0 0.029078 0.0 0.0 0.0</pose>
        <inertia>
          <ixx>0.146596409</ixx>
          <iyy>0.001321394</iyy>
          <izz>0.146596409</izz>
          <ixy>0.0</ixy>
          <ixz>0.0</ixz>
          <iyz>0.0</iyz>
        </inertia>
      </inertial>
      <collision name="collision">
        <geometry>
          <cylinder>
            <length>0.434</length>
            <radius>0.02</radius>
          </cylinder>
        </geometry>
      </collision>
      <visual name="visual">
        <geometry>
          <cylinder>
            <length>0.434</length>
            <radius>0.02</radius>
          </cylinder>
        </geometry>
      </visual>
      <sensor name="right_thigh_contact" type="contact">
        <contact>
          <collision>collision</collision>
        </contact>
      </sensor>
    </link>
    <joint name="right_hip" type="universal">
      <parent>transpelvic_link</parent>
      <child>right_thigh</child>
      <pose>0.0 0.0 0.217 0.0 0.0 0.0</pose>
      <!--Height leg + thigh -->
      <axis>
        <xyz>0.0 1.0 0.0</xyz>
        <limit>
          <lower>-2.043780554</lower>
          <upper>0.0</upper>
        </limit>
        <dynamics>
          <damping>0.05</damping>
        </dynamics>
      </axis>
      <axis2>
        <xyz>1.0 0.0 0.0</xyz>
        <limit>
          <lower>-0.483456203</lower>
          <upper>1.012290966</upper>
        </limit>
        <dynamics>
          <damping>0.05</damping>
        </dynamics>
      </axis2>
      <!-- Joint limits on ball joints not currently supported in gazebo -->
      <!-- 
      <axis3>
        <xyz>0.0 0.0 1.0</xyz>
        <limit>
            <lower>-0.60562925</lower>
            <upper>0.675442421</upper>
        </limit>
        <dynamics>
            <damping>0.05</damping>
        </dynamics>
      </axis3>
      -->
    </joint>
    <link name="left_thigh">
      <pose>0.0 0.0855 0.646 0.0 0.0 0.0</pose>
      <!-- Y coordinate is half the pelvic width. X coordinate is the leg height + 0.5 * thigh height -->
      <inertial>
        <mass>7.46</mass>
        <pose>0.0 0.0 0.029078 0.0 0.0 0.0</pose>
        <inertia>
          <ixx>0.146596409</ixx>
          <iyy>0.001321394</iyy>
          <izz>0.146596409</izz>
          <ixy>0.0</ixy>
          <ixz>0.0</ixz>
          <iyz>0.0</iyz>
        </inertia>
      </inertial>
      <collision name="collision">
        <geometry>
          <cylinder>
            <length>0.434</length>
            <radius>0.02</radius>
          </cylinder>
        </geometry>
      </collision>
      <visual name="visual">
        <geometry>
          <cylinder>
            <length>0.434</length>
            <radius>0.02</radius>
          </cylinder>
        </geometry>
      </visual>
      <sensor name="left_thigh_contact" type="contact">
        <contact>
          <collision>collision</collision>
        </contact>
      </sensor>
    </link>
    <joint name="left_hip" type="universal">
      <parent>transpelvic_link</parent>
      <child>left_thigh</child>
      <pose>0.0 0.0 0.217 0.0 0.0 0.0</pose>
      <!-- leg + thigh height -->
      <axis>
        <xyz>0.0 1.0 0.0</xyz>
        <limit>
          <lower>-2.043780554</lower>
          <upper>0.0</upper>
        </limit>
        <dynamics>
          <damping>0.05</damping>
        </dynamics>
      </axis>
      <axis2>
        <xyz>1.0 0.0 0.0</xyz>
        <limit>
          <lower>-1.012290966</lower>
          <upper>0.483456203</upper>
        </limit>
        <dynamics>
          <damping>0.05</damping>
        </dynamics>
      </axis2>
      <!-- Joint limits on ball joints not currently supported in gazebo -->
      <!--
     <axis3>
        <xyz>0.0 0.0 -1.0</xyz>
        <limit>
            <lower>-0.60562925</lower>
            <upper>0.675442421</upper>
        </limit>
        <dynamics>
            <damping>0.05</damping>
        </dynamics>
      </axis3>
      -->
    </joint>
    <link name="transpelvic_link">
      <pose>0.0 0.0 0.863 0.0 1.570796327 1.570796327</pose>
      <!-- Height of leg + thigh, rotated to ground plane and rotated about the trunk -->
      <!-- No inertial properties. Visualization only -->
      <collision name="collision">
        <geometry>
          <cylinder>
            <length>0.171</length>
            <radius>0.02</radius>
          </cylinder>
        </geometry>
      </collision>
      <visual name="visual">
        <geometry>
          <cylinder>
            <length>0.171</length>
            <radius>0.02</radius>
          </cylinder>
        </geometry>
      </visual>
      <sensor name="transpelvic_contact" type="contact">
        <contact>
          <collision>collision</collision>
        </contact>
      </sensor>
    </link>
    <joint name="lower_spine" type="revolute">
      <parent>trunk</parent>
      <child>transpelvic_link</child>
      <pose>0.0 0.0 0.0 1.570796327 0.0 -1.570796327</pose>
      <axis>
        <xyz>0.0 1 0.0</xyz>
        <limit>
          <lower>0</lower>
          <upper>0</upper>
        </limit>
        <dynamics>
          <damping>0.0</damping>
        </dynamics>
      </axis>
    </joint>
    <joint name="upper_spine" type="revolute">
      <parent>trunk</parent>
      <child>clavicular_link</child>
      <pose>0.0 0.0 0.0 1.570796327 0.0 -1.570796327</pose>
      <axis>
        <xyz>0.0 1 0.0</xyz>
        <limit>
          <lower>0</lower>
          <upper>0</upper>
        </limit>
        <dynamics>
          <damping>0.0</damping>
        </dynamics>
      </axis>
    </joint>
    <link name="clavicular_link">
      <pose>0.0 0.0 1.239 0.0 1.570796327 1.570796327</pose>
      <!-- Height of leg + thigh + trunk, rotated to ground plane and rotated about the trunk -->
      <!-- No inertial properties. Visualization only -->
      <collision name="collision">
        <geometry>
          <cylinder>
            <length>0.163</length>
            <radius>0.02</radius>
          </cylinder>
        </geometry>
      </collision>
      <visual name="visual">
        <geometry>
          <cylinder>
            <length>0.163</length>
            <radius>0.02</radius>
          </cylinder>
        </geometry>
      </visual>
      <sensor name="clavicular_link_contact" type="contact">
        <contact>
          <collision>collision</collision>
        </contact>
      </sensor>
    </link>
    <joint name="neck" type="universal">
      <parent>clavicular_link</parent>
      <child>head_neck</child>
      <pose>0.0 0.0 -0.1625 0.0 0.0 0.0</pose>
      <axis>
        <xyz>0.0 1 0.0</xyz>
        <limit>
          <lower>-0.876155285</lower>
          <upper>1.0978121</upper>
        </limit>
        <dynamics>
          <damping>0.05</damping>
        </dynamics>
      </axis>
      <axis2>
        <xyz>1.0 0.0 0.0</xyz>
        <limit>
          <lower>-0.876155285</lower>
          <upper>1.0978121</upper>
        </limit>
        <dynamics>
          <damping>0.05</damping>
        </dynamics>
      </axis2>
    </joint>
    <link name="head_neck">
      <pose>0.0 0.0 1.4015 0.0 0.0 0.0</pose>
      <!-- Height of leg + thigh + trunk + 0.5 * head-neck -->
      <inertial>
        <mass>6.0426</mass>
        <pose>0.0 0.0 0.1625 0.0 0.0 0.0</pose>
        <inertia>
          <ixx>0.156387114</ixx>
          <iyy>0.000734459</iyy>
          <izz>0.156387114</izz>
          <ixy>0.0</ixy>
          <ixz>0.0</ixz>
          <iyz>0.0</iyz>
        </inertia>
      </inertial>
      <collision name="collision">
        <geometry>
          <cylinder>
            <length>0.325</length>
            <radius>0.02</radius>
          </cylinder>
        </geometry>
      </collision>
      <visual name="visual">
        <geometry>
          <cylinder>
            <length>0.325</length>
            <radius>0.02</radius>
          </cylinder>
        </geometry>
      </visual>
      <sensor name="head_neck_contact" type="contact">
        <contact>
          <collision>collision</collision>
        </contact>
      </sensor>
    </link>
    <link name="right_upper_arm">
      <pose>0.0 -0.0815 1.39 0.0 0.0 0.0</pose>
      <!-- Y coordinate is half the pelvic width. Z coordinate is leg + thigh + trunk + 0.5 * upper arm -->
      <inertial>
        <mass>2.0888</mass>
        <pose>0.0 0.0 -0.019328 0.0 0.0 0.0</pose>
        <inertia>
          <ixx>0.019752519</ixx>
          <iyy>9.28219E-05</iyy>
          <izz>0.019752519</izz>
          <ixy>0.0</ixy>
          <ixz>0.0</ixz>
          <iyz>0.0</iyz>
        </inertia>
      </inertial>
      <collision name="collision">
        <geometry>
          <cylinder>
            <length>0.302</length>
            <radius>0.02</radius>
          </cylinder>
        </geometry>
      </collision>
      <visual name="visual">
        <geometry>
          <cylinder>
            <length>0.302</length>
            <radius>0.02</radius>
          </cylinder>
        </geometry>
      </visual>
      <sensor name="right_upper_arm_contact" type="contact">
        <contact>
          <collision>collision</collision>
        </contact>
      </sensor>
    </link>
    <joint name="right_shoulder" type="universal">
      <parent>clavicular_link</parent>
      <child>right_upper_arm</child>
      <pose>0.0 0.0 -0.151 0.0 0.0 0.0</pose>
      <axis>
        <xyz>0.0 1.0 0.0</xyz>
        <limit>
          <lower>-0.230383461</lower>
          <upper>3.141592654</upper>
          <!-- Gazebo fails setting joints to values greater than pi 3.371976115 -->
        </limit>
        <dynamics>
          <damping>0.05</damping>
        </dynamics>
      </axis>
      <axis2>
        <xyz>1.0 0.0 0.0</xyz>
        <limit>
          <lower>-2.305579942</lower>
          <upper>0.88662726</upper>
        </limit>
        <dynamics>
          <damping>0.05</damping>
        </dynamics>
      </axis2>
      <!-- Joint limits on ball joints not currently supported in gazebo -->
      <!--
     <axis3>
        <xyz>0.0 0.0 1.0</xyz>
        <limit>
            <lower>-2.305579942</lower>
            <upper>0.88662726</upper>
        </limit>
        <dynamics>
            <damping>0.05</damping>
        </dynamics>
      </axis3>
      -->
    </joint>
    <link name="left_upper_arm">
      <pose>0.0 0.0815 1.39 0.0 0.0 0.0</pose>
      <!-- Y coordinate is half the pelvic width. Z coordinate is leg + thigh + trunk + 0.5 * upper arm -->
      <inertial>
        <mass>2.0888</mass>
        <pose>0.0 0.0 -0.019328 0.0 0.0 0.0</pose>
        <inertia>
          <ixx>0.019752519</ixx>
          <iyy>9.28219E-05</iyy>
          <izz>0.019752519</izz>
          <ixy>0.0</ixy>
          <ixz>0.0</ixz>
          <iyz>0.0</iyz>
        </inertia>
      </inertial>
      <collision name="collision">
        <geometry>
          <cylinder>
            <length>0.302</length>
            <radius>0.02</radius>
          </cylinder>
        </geometry>
      </collision>
      <visual name="visual">
        <geometry>
          <cylinder>
            <length>0.302</length>
            <radius>0.02</radius>
          </cylinder>
        </geometry>
      </visual>
      <sensor name="left_upper_arm_contact" type="contact">
        <contact>
          <collision>collision</collision>
        </contact>
      </sensor>
    </link>
    <joint name="left_shoulder" type="universal">
      <parent>clavicular_link</parent>
      <child>left_upper_arm</child>
      <pose>0.0 0.0 -0.151 0.0 0.0 0.0</pose>
      <axis>
        <xyz>0.0 1.0 0.0</xyz>
        <limit>
          <lower>-0.230383461</lower>
          <upper>3.141592654</upper>
          <!-- Gazebo fails setting joints to values greater than pi 3.371976115 -->
        </limit>
        <dynamics>
          <damping>0.05</damping>
        </dynamics>
      </axis>
      <axis2>
        <xyz>1.0 0.0 0.0</xyz>
        <limit>
          <lower>-0.88662726</lower>
          <upper>2.305579942</upper>
        </limit>
        <dynamics>
          <damping>0.05</damping>
        </dynamics>
      </axis2>
      <!-- Joint limits on ball joints not currently supported in gazebo -->
      <!--
     <axis3>
        <xyz>0.0 0.0 -1.0</xyz>
        <limit>
            <lower>-2.305579942</lower>
            <upper>0.88662726</upper>
        </limit> 
        <dynamics>
            <damping>0.05</damping>
        </dynamics>
      </axis3>
      -->
    </joint>
    <link name="right_forearm">
      <pose>0.0 -0.0815 1.677 0.0 0.0 0.0</pose>
      <!-- Y coordinate is half the pelvic width. Z coordinate is leg + thigh + trunk + upper arm + 0.5 * forearm -->
      <inertial>
        <mass>1.1936</mass>
        <pose>0.0 0.0 -0.01904 0.0 0.0 0.0</pose>
        <inertia>
          <ixx>0.008107405</ixx>
          <iyy>4.65747E-05</iyy>
          <izz>0.008107405</izz>
          <ixy>0.0</ixy>
          <ixz>0.0</ixz>
          <iyz>0.0</iyz>
        </inertia>
      </inertial>
      <collision name="collision">
        <geometry>
          <cylinder>
            <length>0.272</length>
            <radius>0.02</radius>
          </cylinder>
        </geometry>
      </collision>
      <visual name="visual">
        <geometry>
          <cylinder>
            <length>0.272</length>
            <radius>0.02</radius>
          </cylinder>
        </geometry>
      </visual>
      <sensor name="right_forearm_contact" type="contact">
        <contact>
          <collision>collision</collision>
        </contact>
      </sensor>
    </link>
    <joint name="right_elbow" type="revolute">
      <parent>right_upper_arm</parent>
      <child>right_forearm</child>
      <pose>0.0 0.0 -0.136 0.0 0.0 0.0</pose>
      <axis>
        <xyz>0.0 -1 0.0</xyz>
        <limit>
          <lower>0</lower>
          <upper>2.460914245</upper>
        </limit>
        <dynamics>
          <damping>0.05</damping>
        </dynamics>
      </axis>
    </joint>
    <link name="left_forearm">
      <pose>0.0 0.0815 1.677 0.0 0.0 0.0</pose>
      <!-- Y coordinate is half the pelvic width. Z coordinate is leg + thigh + trunk + upper arm + 0.5 * forearm -->
      <inertial>
        <mass>1.1936</mass>
        <pose>0.0 0.0 -0.01904 0.0 0.0 0.0</pose>
        <inertia>
          <ixx>0.008107405</ixx>
          <iyy>4.65747E-05</iyy>
          <izz>0.008107405</izz>
          <ixy>0.0</ixy>
          <ixz>0.0</ixz>
          <iyz>0.0</iyz>
        </inertia>
      </inertial>
      <collision name="collision">
        <geometry>
          <cylinder>
            <length>0.272</length>
            <radius>0.02</radius>
          </cylinder>
        </geometry>
      </collision>
      <visual name="visual">
        <geometry>
          <cylinder>
            <length>0.272</length>
            <radius>0.02</radius>
          </cylinder>
        </geometry>
      </visual>
      <sensor name="left_forearm_contact" type="contact">
        <contact>
          <collision>collision</collision>
        </contact>
      </sensor>
    </link>
    <joint name="left_elbow" type="revolute">
      <parent>left_upper_arm</parent>
      <child>left_forearm</child>
      <pose>0.0 0.0 -0.136 0.0 0.0 0.0</pose>
      <axis>
        <xyz>0.0 -1 0.0</xyz>
        <limit>
          <lower>0</lower>
          <upper>2.460914245</upper>
        </limit>
        <dynamics>
          <damping>0.05</damping>
        </dynamics>
      </axis>
    </joint>
    <link name="right_hand">
      <pose>0.0 -0.0815 1.848 0.0 0.0 0.0</pose>
      <!-- Y coordinate is half the pelvic width. Z coordinate is leg + thigh + trunk + upper arm + forearm + 0.5 * hand -->
      <inertial>
        <mass>0.4476</mass>
        <pose>0.0 0.0 0.00042 0.0 0.0 0.0</pose>
        <inertia>
          <ixx>0.000193464</ixx>
          <iyy>7.36224E-06</iyy>
          <izz>0.000193464</izz>
          <ixy>0.0</ixy>
          <ixz>0.0</ixz>
          <iyz>0.0</iyz>
        </inertia>
      </inertial>
      <collision name="collision">
        <geometry>
          <cylinder>
            <length>0.07</length>
            <radius>0.02</radius>
          </cylinder>
        </geometry>
      </collision>
      <visual name="visual">
        <geometry>
          <cylinder>
            <length>0.07</length>
            <radius>0.02</radius>
          </cylinder>
        </geometry>
      </visual>
      <sensor name="right_hand_contact" type="contact">
        <contact>
          <collision>collision</collision>
        </contact>
      </sensor>
    </link>
    <joint name="right_wrist" type="universal">
      <parent>right_forearm</parent>
      <child>right_hand</child>
      <pose>0.0 0.0 -0.035 0.0 0.0 0.0</pose>
      <axis>
        <xyz>0.0 1.0 0.0</xyz>
        <limit>
          <lower>-1.780235837</lower>
          <upper>1.651081472</upper>
        </limit>
        <dynamics>
          <damping>0.05</damping>
        </dynamics>
      </axis>
      <axis2>
        <xyz>1.0 0.0 0.0</xyz>
        <limit>
          <lower>-0.438077642</lower>
          <upper>0.808087444</upper>
        </limit>
        <dynamics>
          <damping>0.05</damping>
        </dynamics>
      </axis2>
    </joint>
    <link name="left_hand">
      <pose>0.0 0.0815 1.848 0.0 0.0 0.0</pose>
      <!-- Y coordinate is half the pelvic width. Z coordinate is leg + thigh + trunk + upper arm + forearm + 0.5 * hand -->
      <inertial>
        <mass>0.4476</mass>
        <pose>0.0 0.0 0.00042 0.0 0.0 0.0</pose>
        <inertia>
          <ixx>0.000193464</ixx>
          <iyy>7.36224E-06</iyy>
          <izz>0.000193464</izz>
          <ixy>0.0</ixy>
          <ixz>0.0</ixz>
          <iyz>0.0</iyz>
        </inertia>
      </inertial>
      <collision name="collision">
        <geometry>
          <cylinder>
            <length>0.07</length>
            <radius>0.02</radius>
          </cylinder>
        </geometry>
      </collision>
      <visual name="visual">
        <geometry>
          <cylinder>
            <length>0.07</length>
            <radius>0.02</radius>
          </cylinder>
        </geometry>
      </visual>
      <sensor name="left_hand_contact" type="contact">
        <contact>
          <collision>collision</collision>
        </contact>
      </sensor>
    </link>
    <joint name="left_wrist" type="universal">
      <parent>left_forearm</parent>
      <child>left_hand</child>
      <pose>0.0 0.0 -0.035 0.0 0.0 0.0</pose>
      <axis>
        <xyz>0.0 1.0 0.0</xyz>
        <limit>
          <lower>-1.651081472</lower>
          <upper>1.780235837</upper>
        </limit>
        <dynamics>
          <damping>0.05</damping>
        </dynamics>
      </axis>
      <axis2>
        <xyz>1.0 0.0 0.0</xyz>
        <limit>
          <lower>-0.438077642</lower>
          <upper>0.808087444</upper>
        </limit>
        <dynamics>
          <damping>0.05</damping>
        </dynamics>
      </axis2>
    </joint>
    <!-- <xacro:human xoffset="0" yoffset="0" zoffset="0.0"/>-->
    <!-- Base pose -->
  </model>
</sdf>

